0906/output/fill_logic_diagnostic.json
{
  "as_of": "2026-09-06",
  "instrument": "HK 07709",
  "test_days": 19,
  "comparison": "classic AS; original daily parameters held fixed",
  "old_fill_rule": "qualifying future trade price",
  "new_fill_rule": "qualifying future trade price OR opposite L1 best quote",
  "summary": [
    {
      "fill_mode": "through",
      "old_fills": 34544,
      "new_fills": 34746,
      "new_trade_price_fills": 33461,
      "new_best_quote_fills": 1285,
      "new_best_ask_fills": 647,
      "new_best_bid_fills": 638,
      "old_gross_pnl_hkd": 43516.000335693316,
      "new_gross_pnl_hkd": 42504.00033569332,
      "old_fees_hkd": 63472.64977990701,
      "new_fees_hkd": 63896.48858790701,
      "old_net_pnl_hkd": -19956.649444213675,
      "new_net_pnl_hkd": -21392.488252213676,
      "added_fills": 202,
      "new_trade_price_fill_share": 0.9630173257353365,
      "new_best_quote_fill_share": 0.036982674264663555,
      "gross_pnl_delta_hkd": -1011.9999999999927,
      "additional_fees_hkd": 423.8388080000004,
      "net_pnl_delta_hkd": -1435.8388080000004,
      "gross_delta_per_added_fill_hkd": -5.0099009900989735,
      "fee_delta_per_added_fill_hkd": 2.0982119207920813,
      "net_delta_per_added_fill_hkd": -7.108112910891092,
      "days_new_rule_better": 4,
      "days_new_rule_worse": 15,
      "full_walk_forward_old_net_pnl_hkd": -19956.649444213697,
      "full_walk_forward_new_net_pnl_hkd": -21085.96771442194,
      "full_walk_forward_net_delta_hkd": -1129.3182702082413
    },
    {
      "fill_mode": "touch",
      "old_fills": 50401,
      "new_fills": 50639,
      "new_trade_price_fills": 48677,
      "new_best_quote_fills": 1962,
      "new_best_ask_fills": 1038,
      "new_best_bid_fills": 924,
      "old_gross_pnl_hkd": 99243.9981384277,
      "new_gross_pnl_hkd": 98613.99813842772,
      "old_fees_hkd": 88840.89591206763,
      "new_fees_hkd": 89314.96534606763,
      "old_net_pnl_hkd": 10403.102226360043,
      "new_net_pnl_hkd": 9299.032792360056,
      "added_fills": 238,
      "new_trade_price_fill_share": 0.9612551590671222,
      "new_best_quote_fill_share": 0.03874484093287782,
      "gross_pnl_delta_hkd": -629.9999999999854,
      "additional_fees_hkd": 474.06943400000455,
      "net_pnl_delta_hkd": -1104.0694339999864,
      "gross_delta_per_added_fill_hkd": -2.6470588235293504,
      "fee_delta_per_added_fill_hkd": 1.9918883781512797,
      "net_delta_per_added_fill_hkd": -4.638947201680615,
      "days_new_rule_better": 4,
      "days_new_rule_worse": 15,
      "full_walk_forward_old_net_pnl_hkd": 10403.102226360075,
      "full_walk_forward_new_net_pnl_hkd": 9539.364532556807,
      "full_walk_forward_net_delta_hkd": -863.7376938032685
    }
  ],
  "daily": [
    {
      "date": "2026-07-03",
      "fill_mode": "through",
      "old_fills": 1909,
      "new_fills": 1917,
      "new_trade_price_fills": 1872,
      "new_best_quote_fills": 45,
      "new_best_ask_fills": 28,
      "new_best_bid_fills": 17,
      "old_gross_pnl_hkd": 5648.000152587891,
      "new_gross_pnl_hkd": 5404.000152587891,
      "old_fees_hkd": 6009.192571957733,
      "new_fees_hkd": 6034.456079957733,
      "old_net_pnl_hkd": -361.1924193698387,
      "new_net_pnl_hkd": -630.4559273698387
    },
    {
      "date": "2026-07-03",
      "fill_mode": "touch",
      "old_fills": 2224,
      "new_fills": 2236,
      "new_trade_price_fills": 2177,
      "new_best_quote_fills": 59,
      "new_best_ask_fills": 38,
      "new_best_bid_fills": 21,
      "old_gross_pnl_hkd": 7256.0,
      "new_gross_pnl_hkd": 7290.0,
      "old_fees_hkd": 7001.270288000001,
      "new_fees_hkd": 7038.011014000001,
      "old_net_pnl_hkd": 254.72971199998847,
      "new_net_pnl_hkd": 251.9889859999903
    },
    {
      "date": "2026-07-06",
      "fill_mode": "through",
      "old_fills": 1556,
      "new_fills": 1588,
      "new_trade_price_fills": 1427,
      "new_best_quote_fills": 161,
      "new_best_ask_fills": 76,
      "new_best_bid_fills": 85,
      "old_gross_pnl_hkd": 3114.0,
      "new_gross_pnl_hkd": 3008.0,
      "old_fees_hkd": 4693.071946,
      "new_fees_hkd": 4789.924996,
      "old_net_pnl_hkd": -1579.07194599999,
      "new_net_pnl_hkd": -1781.9249959999906
    },
    {
      "date": "2026-07-06",
      "fill_mode": "touch",
      "old_fills": 1854,
      "new_fills": 1896,
      "new_trade_price_fills": 1706,
      "new_best_quote_fills": 190,
      "new_best_ask_fills": 95,
      "new_best_bid_fills": 95,
      "old_gross_pnl_hkd": 5138.0,
      "new_gross_pnl_hkd": 5218.0,
      "old_fees_hkd": 5591.282118,
      "new_fees_hkd": 5716.960342,
      "old_net_pnl_hkd": -453.2821180000001,
      "new_net_pnl_hkd": -498.96034200000213
    },
    {
      "date": "2026-07-07",
      "fill_mode": "through",
      "old_fills": 2060,
      "new_fills": 2064,
      "new_trade_price_fills": 2012,
      "new_best_quote_fills": 52,
      "new_best_ask_fills": 37,
      "new_best_bid_fills": 15,
      "old_gross_pnl_hkd": 15028.0,
      "new_gross_pnl_hkd": 14960.0,
      "old_fees_hkd": 5159.897276000001,
      "new_fees_hkd": 5169.754044,
      "old_net_pnl_hkd": 9868.102723999993,
      "new_net_pnl_hkd": 9790.245955999993
    },
    {
      "date": "2026-07-07",
      "fill_mode": "touch",
      "old_fills": 2532,
      "new_fills": 2538,
      "new_trade_price_fills": 2458,
      "new_best_quote_fills": 80,
      "new_best_ask_fills": 57,
      "new_best_bid_fills": 23,
      "old_gross_pnl_hkd": 18094.0,
      "new_gross_pnl_hkd": 17956.0,
      "old_fees_hkd": 6341.287318000001,
      "new_fees_hkd": 6355.833696000001,
      "old_net_pnl_hkd": 11752.712681999988,
      "new_net_pnl_hkd": 11600.16630399999
    },
    {
      "date": "2026-07-08",
      "fill_mode": "through",
      "old_fills": 2582,
      "new_fills": 2594,
      "new_trade_price_fills": 2476,
      "new_best_quote_fills": 118,
      "new_best_ask_fills": 59,
      "new_best_bid_fills": 59,
      "old_gross_pnl_hkd": 5050.0,
      "new_gross_pnl_hkd": 4896.0,
      "old_fees_hkd": 6430.669678,
      "new_fees_hkd": 6460.534156000001,
      "old_net_pnl_hkd": -1380.6696779999966,
      "new_net_pnl_hkd": -1564.5341559999997
    },
    {
      "date": "2026-07-08",
      "fill_mode": "touch",
      "old_fills": 3371,
      "new_fills": 3387,
      "new_trade_price_fills": 3230,
      "new_best_quote_fills": 157,
      "new_best_ask_fills": 77,
      "new_best_bid_fills": 80,
      "old_gross_pnl_hkd": 9251.999877929688,
      "new_gross_pnl_hkd": 9159.999877929688,
      "old_fees_hkd": 8427.723891966187,
      "new_fees_hkd": 8467.753715966186,
      "old_net_pnl_hkd": 824.2759859634953,
      "new_net_pnl_hkd": 692.246161963496
    },
    {
      "date": "2026-07-09",
      "fill_mode": "through",
      "old_fills": 2396,
      "new_fills": 2418,
      "new_trade_price_fills": 2303,
      "new_best_quote_fills": 115,
      "new_best_ask_fills": 69,
      "new_best_bid_fills": 46,
      "old_gross_pnl_hkd": 4682.0,
      "new_gross_pnl_hkd": 4672.0,
      "old_fees_hkd": 5887.847182,
      "new_fees_hkd": 5940.742548,
      "old_net_pnl_hkd": -1205.8471820000013,
      "new_net_pnl_hkd": -1268.742548000002
    },
    {
      "date": "2026-07-09",
      "fill_mode": "touch",
      "old_fills": 3222,
      "new_fills": 3240,
      "new_trade_price_fills": 3062,
      "new_best_quote_fills": 178,
      "new_best_ask_fills": 120,
      "new_best_bid_fills": 58,
      "old_gross_pnl_hkd": 8866.0,
      "new_gross_pnl_hkd": 8860.0,
      "old_fees_hkd": 7913.909390000001,
      "new_fees_hkd": 7956.9158560000005,
      "old_net_pnl_hkd": 952.0906099999911,
      "new_net_pnl_hkd": 903.0841439999931
    },
    {
      "date": "2026-07-10",
      "fill_mode": "through",
      "old_fills": 1447,
      "new_fills": 1469,
      "new_trade_price_fills": 1390,
      "new_best_quote_fills": 79,
      "new_best_ask_fills": 45,
      "new_best_bid_fills": 34,
      "old_gross_pnl_hkd": 2664.0003356933594,
      "new_gross_pnl_hkd": 2750.0003356933594,
